2021-03-23 21:00:44.860492: UnableToWorkException, Traceback:   File "app.py", line 23, in <module>
    main()

